Workbook

Sheet DATA ENTRY FORM2
D3: SOUTHVILLE INTERNATIONAL SCHOOL AND COLLEGES
D4: SUPPLIER EVALUATION FORM
C7: Evaluation Date: | D7: 44498
C9: Company Name: | D9: Atlas Super Flags | H9: PRF No.: | I9: 102099 | M9: Requisitioner Details
C11: Address: | H11: PO Number: | I11: PO29704 | M11: Requisitioner Name:
C13: Item/s Delivered: | D13: =IFERROR(__xludf.DUMMYFUNCTION("IFERROR(FILTER('PRF Details'!D3:D48, 'PRF Details'!A3:A48 = I9))"),"INTERNATIONAL FLAGS ") -> INTERNATIONAL FLAGS | H13: Remarks: | M13: Email Address:
C17: CRITERIA | F17: Purchasing | G17: Requisitioner | H17: AMD | I17: REMARKS (Kindly put reasons for item below 4)
C18: A. Accurate Delivery/quality | F18: 5 | G18: 5 | H18: 5
C19: B. Competitive Price | F19: 5 | G19: 5 | H19: 5
C20: C. Timeliness of Delivery | F20: 5 | G20: 5 | H20: 5
C21: D. After Sales Service | F21: 5 | G21: 5 | H21: 5
C22: E. Compliance with Regulatory Requirements and School Policies | F22: 5 | G22: N/A | H22: N/A
E24: AVERAGE | F24: =IFERROR(AVERAGE(F18:F22),"") -> 5 | G24: =IFERROR(AVERAGE(G18:G21),"") -> 5 | H24: =IFERROR(AVERAGE(H18:H21),"") -> 5
E26: FINAL RATING | F26: =IFERROR(AVERAGE(F24:H24),"") -> 5
C28: RUBRIC | I28: RECOMMENDATIONS
C29: 5 EXCELLENT - Supplier conformed to all requirements, accurate delivery, good quality, competitive price, timeliness of delivery, after sales, compliance to regulatory requirements. | I29: 4.5 - 5.0 || Strongly Recommended
C30: 4 VERY GOOD - Supplier conformed to all requirements, accurate delivery, good quality, competitive price, timeliness of delivery, after sales, compliance to regulatory requirements. | I30: 4.0 - 4.49 || Recommended
C31: 3 GOOD - Supplier conformed to all requirements, accurate delivery, good quality, competitive price, timeliness of delivery, after sales, compliance to regulatory requirements (1-2 deviations). | I31: 3.5 - 3.99 || Acceptable
C32: 2 FAIR - Supplier conformed to requirements, specifications and standards of good with 3-4 non-conformance issues. | I32: 3.0 - 3.49 || Acceptable w/ some Reservation
C33: 1 POOR - Supplier conformed to few requirements, specifications and standards of good workmanship with 6 or more non-conformance. | I33: Below 3.0 || Not Recommended
C35: Note: This form is used after the delivery of item/s. This will be done per transaction w/ supplier
C37: CONFORMED BY
C39: SUPPLIER
C41: EVALUATOR | E41: NOTED BY | H41: APPROVED BY
I42: Dr. Jocelyn P. Tizon
C43: Name & Signature | F43: Next Level Head/Manager | I43: President

Sheet July 2024
B1: March | C1: 2024 | D1: Average: | E1: =AVERAGE(E9:E103) -> 4.6614236 | H1: Company | I1: Month Start | J1: Month End | K1: Year
H2: Amazon | I2: July | J2: December | K2: 2024
A4: Supplier Evalution Report for the Month of July 2024
D7: Average: | E7: =AVERAGE(E9:E15) -> 4.3792857
A8: # | B8: PRF# | C8: PO# | D8: DATE | E8: AVERAGE | G8: # | H8: PRF# | I8: PO# | J8: DATE | K8: SUPPLIER | L8: AVERAGE
A9: 1 | B9: =IFERROR(__xludf.DUMMYFUNCTION("IFERROR(FILTER(DATABASE!A:B, TEXT(DATABASE!D:D, ""MMMM"")=B1, YEAR(DATABASE!D:D)=C1), ""No Data Found"")"),104215.0) -> 104215 | C9: =IFERROR(__xludf.DUMMYFUNCTION("""COMPUTED_VALUE"""),"PO31159") -> PO31159 | D9: =IFERROR(__xludf.DUMMYFUNCTION("FILTER(DATABASE!D:D, TEXT(DATABASE!D:D, ""MMMM"")=B1, YEAR(DATABASE!D:D)=C1)"),45352.0) -> 45352 | E9: =IFERROR(__xludf.DUMMYFUNCTION("FILTER(DATABASE!AC:AC, TEXT(DATABASE!D:D, ""MMMM"")=B1, YEAR(DATABASE!D:D)=C1)"),5.0) -> 5 | G9: 1
A10: 2 | B10: =IFERROR(__xludf.DUMMYFUNCTION("""COMPUTED_VALUE"""),104053.0) -> 104053 | C10: =IFERROR(__xludf.DUMMYFUNCTION("""COMPUTED_VALUE"""),"PO31185") -> PO31185 | D10: =IFERROR(__xludf.DUMMYFUNCTION("""COMPUTED_VALUE"""),45353.0) -> 45353 | E10: =IFERROR(__xludf.DUMMYFUNCTION("""COMPUTED_VALUE"""),4.575) -> 4.575 | G10: 2
A11: 3 | B11: =IFERROR(__xludf.DUMMYFUNCTION("""COMPUTED_VALUE"""),104230.0) -> 104230 | C11: =IFERROR(__xludf.DUMMYFUNCTION("""COMPUTED_VALUE"""),"PO31193") -> PO31193 | D11: =IFERROR(__xludf.DUMMYFUNCTION("""COMPUTED_VALUE"""),45355.0) -> 45355 | E11: =IFERROR(__xludf.DUMMYFUNCTION("""COMPUTED_VALUE"""),4.75) -> 4.75 | G11: 3
A12: 4 | B12: =IFERROR(__xludf.DUMMYFUNCTION("""COMPUTED_VALUE"""),104248.0) -> 104248 | C12: =IFERROR(__xludf.DUMMYFUNCTION("""COMPUTED_VALUE"""),"PO31178") -> PO31178 | D12: =IFERROR(__xludf.DUMMYFUNCTION("""COMPUTED_VALUE"""),45356.0) -> 45356 | E12: =IFERROR(__xludf.DUMMYFUNCTION("""COMPUTED_VALUE"""),4.5) -> 4.5 | G12: 4
A13: 5 | B13: =IFERROR(__xludf.DUMMYFUNCTION("""COMPUTED_VALUE"""),104186.0) -> 104186 | C13: =IFERROR(__xludf.DUMMYFUNCTION("""COMPUTED_VALUE"""),"PO31179") -> PO31179 | D13: =IFERROR(__xludf.DUMMYFUNCTION("""COMPUTED_VALUE"""),45356.0) -> 45356 | E13: =IFERROR(__xludf.DUMMYFUNCTION("""COMPUTED_VALUE"""),4.496666666666667) -> 4.4966667 | G13: 5
A14: 6 | B14: =IFERROR(__xludf.DUMMYFUNCTION("""COMPUTED_VALUE"""),104102.0) -> 104102 | C14: =IFERROR(__xludf.DUMMYFUNCTION("""COMPUTED_VALUE"""),"PO31146") -> PO31146 | D14: =IFERROR(__xludf.DUMMYFUNCTION("""COMPUTED_VALUE"""),45356.0) -> 45356 | E14: =IFERROR(__xludf.DUMMYFUNCTION("""COMPUTED_VALUE"""),3.6666666666666665) -> 3.6666667 | G14: 6
A15: 7 | B15: =IFERROR(__xludf.DUMMYFUNCTION("""COMPUTED_VALUE"""),104102.0) -> 104102 | C15: =IFERROR(__xludf.DUMMYFUNCTION("""COMPUTED_VALUE"""),"PO31147") -> PO31147 | D15: =IFERROR(__xludf.DUMMYFUNCTION("""COMPUTED_VALUE"""),45356.0) -> 45356 | E15: =IFERROR(__xludf.DUMMYFUNCTION("""COMPUTED_VALUE"""),3.6666666666666665) -> 3.6666667 | G15: 7
A16: 8 | B16: =IFERROR(__xludf.DUMMYFUNCTION("""COMPUTED_VALUE"""),104179.0) -> 104179 | C16: =IFERROR(__xludf.DUMMYFUNCTION("""COMPUTED_VALUE"""),"PO31191") -> PO31191 | D16: =IFERROR(__xludf.DUMMYFUNCTION("""COMPUTED_VALUE"""),45357.0) -> 45357 | E16: =IFERROR(__xludf.DUMMYFUNCTION("""COMPUTED_VALUE"""),4.496666666666667) -> 4.4966667 | G16: 8
A17: 9 | B17: =IFERROR(__xludf.DUMMYFUNCTION("""COMPUTED_VALUE"""),104208.0) -> 104208 | C17: =IFERROR(__xludf.DUMMYFUNCTION("""COMPUTED_VALUE"""),"PO31190") -> PO31190 | D17: =IFERROR(__xludf.DUMMYFUNCTION("""COMPUTED_VALUE"""),45357.0) -> 45357 | E17: =IFERROR(__xludf.DUMMYFUNCTION("""COMPUTED_VALUE"""),4.5) -> 4.5 | G17: 9
A18: 10 | B18: =IFERROR(__xludf.DUMMYFUNCTION("""COMPUTED_VALUE"""),104176.0) -> 104176 | C18: =IFERROR(__xludf.DUMMYFUNCTION("""COMPUTED_VALUE"""),"PO31155") -> PO31155 | D18: =IFERROR(__xludf.DUMMYFUNCTION("""COMPUTED_VALUE"""),45358.0) -> 45358 | E18: =IFERROR(__xludf.DUMMYFUNCTION("""COMPUTED_VALUE"""),5.0) -> 5 | G18: 10
A19: 11 | B19: =IFERROR(__xludf.DUMMYFUNCTION("""COMPUTED_VALUE"""),104199.0) -> 104199 | C19: =IFERROR(__xludf.DUMMYFUNCTION("""COMPUTED_VALUE"""),"PO31173") -> PO31173 | D19: =IFERROR(__xludf.DUMMYFUNCTION("""COMPUTED_VALUE"""),45359.0) -> 45359 | E19: =IFERROR(__xludf.DUMMYFUNCTION("""COMPUTED_VALUE"""),4.5) -> 4.5 | G19: 11
A20: 12 | B20: =IFERROR(__xludf.DUMMYFUNCTION("""COMPUTED_VALUE"""),104178.0) -> 104178 | C20: =IFERROR(__xludf.DUMMYFUNCTION("""COMPUTED_VALUE"""),"PO31174") -> PO31174 | D20: =IFERROR(__xludf.DUMMYFUNCTION("""COMPUTED_VALUE"""),45359.0) -> 45359 | E20: =IFERROR(__xludf.DUMMYFUNCTION("""COMPUTED_VALUE"""),4.496666666666667) -> 4.4966667
A21: 13 | B21: =IFERROR(__xludf.DUMMYFUNCTION("""COMPUTED_VALUE"""),104300.0) -> 104300 | C21: =IFERROR(__xludf.DUMMYFUNCTION("""COMPUTED_VALUE"""),"PO31203") -> PO31203 | D21: =IFERROR(__xludf.DUMMYFUNCTION("""COMPUTED_VALUE"""),45360.0) -> 45360 | E21: =IFERROR(__xludf.DUMMYFUNCTION("""COMPUTED_VALUE"""),4.833333333333333) -> 4.8333333
A22: 14 | B22: =IFERROR(__xludf.DUMMYFUNCTION("""COMPUTED_VALUE"""),104261.0) -> 104261 | C22: =IFERROR(__xludf.DUMMYFUNCTION("""COMPUTED_VALUE"""),"PO31199") -> PO31199 | D22: =IFERROR(__xludf.DUMMYFUNCTION("""COMPUTED_VALUE"""),45360.0) -> 45360 | E22: =IFERROR(__xludf.DUMMYFUNCTION("""COMPUTED_VALUE"""),5.0) -> 5
A23: 15 | B23: =IFERROR(__xludf.DUMMYFUNCTION("""COMPUTED_VALUE"""),104270.0) -> 104270 | C23: =IFERROR(__xludf.DUMMYFUNCTION("""COMPUTED_VALUE"""),"PO31211") -> PO31211 | D23: =IFERROR(__xludf.DUMMYFUNCTION("""COMPUTED_VALUE"""),45360.0) -> 45360 | E23: =IFERROR(__xludf.DUMMYFUNCTION("""COMPUTED_VALUE"""),4.75) -> 4.75
A24: 16 | B24: =IFERROR(__xludf.DUMMYFUNCTION("""COMPUTED_VALUE"""),104233.0) -> 104233 | C24: =IFERROR(__xludf.DUMMYFUNCTION("""COMPUTED_VALUE"""),"PO31192") -> PO31192 | D24: =IFERROR(__xludf.DUMMYFUNCTION("""COMPUTED_VALUE"""),45362.0) -> 45362 | E24: =IFERROR(__xludf.DUMMYFUNCTION("""COMPUTED_VALUE"""),4.75) -> 4.75
A25: 17 | B25: =IFERROR(__xludf.DUMMYFUNCTION("""COMPUTED_VALUE"""),104234.0) -> 104234 | D25: =IFERROR(__xludf.DUMMYFUNCTION("""COMPUTED_VALUE"""),45362.0) -> 45362 | E25: =IFERROR(__xludf.DUMMYFUNCTION("""COMPUTED_VALUE"""),4.75) -> 4.75
A26: 18 | B26: =IFERROR(__xludf.DUMMYFUNCTION("""COMPUTED_VALUE"""),103963.0) -> 103963 | C26: =IFERROR(__xludf.DUMMYFUNCTION("""COMPUTED_VALUE"""),"PO31181") -> PO31181 | D26: =IFERROR(__xludf.DUMMYFUNCTION("""COMPUTED_VALUE"""),45363.0) -> 45363 | E26: =IFERROR(__xludf.DUMMYFUNCTION("""COMPUTED_VALUE"""),4.666666666666667) -> 4.6666667
A27: 19 | B27: =IFERROR(__xludf.DUMMYFUNCTION("""COMPUTED_VALUE"""),104061.0) -> 104061 | C27: =IFERROR(__xludf.DUMMYFUNCTION("""COMPUTED_VALUE"""),"PO31131") -> PO31131 | D27: =IFERROR(__xludf.DUMMYFUNCTION("""COMPUTED_VALUE"""),45365.0) -> 45365 | E27: =IFERROR(__xludf.DUMMYFUNCTION("""COMPUTED_VALUE"""),4.833333333333333) -> 4.8333333
A28: 20 | B28: =IFERROR(__xludf.DUMMYFUNCTION("""COMPUTED_VALUE"""),104269.0) -> 104269 | C28: =IFERROR(__xludf.DUMMYFUNCTION("""COMPUTED_VALUE"""),"PO31200") -> PO31200 | D28: =IFERROR(__xludf.DUMMYFUNCTION("""COMPUTED_VALUE"""),45365.0) -> 45365 | E28: =IFERROR(__xludf.DUMMYFUNCTION("""COMPUTED_VALUE"""),4.75) -> 4.75
A29: 21 | B29: =IFERROR(__xludf.DUMMYFUNCTION("""COMPUTED_VALUE"""),104346.0) -> 104346 | C29: =IFERROR(__xludf.DUMMYFUNCTION("""COMPUTED_VALUE"""),"PO31230") -> PO31230 | D29: =IFERROR(__xludf.DUMMYFUNCTION("""COMPUTED_VALUE"""),45366.0) -> 45366 | E29: =IFERROR(__xludf.DUMMYFUNCTION("""COMPUTED_VALUE"""),5.0) -> 5
A30: 22 | B30: =IFERROR(__xludf.DUMMYFUNCTION("""COMPUTED_VALUE"""),104271.0) -> 104271 | C30: =IFERROR(__xludf.DUMMYFUNCTION("""COMPUTED_VALUE"""),"PO31212") -> PO31212 | D30: =IFERROR(__xludf.DUMMYFUNCTION("""COMPUTED_VALUE"""),45366.0) -> 45366 | E30: =IFERROR(__xludf.DUMMYFUNCTION("""COMPUTED_VALUE"""),4.75) -> 4.75
A31: 23 | B31: =IFERROR(__xludf.DUMMYFUNCTION("""COMPUTED_VALUE"""),104272.0) -> 104272 | C31: =IFERROR(__xludf.DUMMYFUNCTION("""COMPUTED_VALUE"""),"PO31213") -> PO31213 | D31: =IFERROR(__xludf.DUMMYFUNCTION("""COMPUTED_VALUE"""),45366.0) -> 45366 | E31: =IFERROR(__xludf.DUMMYFUNCTION("""COMPUTED_VALUE"""),4.75) -> 4.75
A32: 24 | B32: =IFERROR(__xludf.DUMMYFUNCTION("""COMPUTED_VALUE"""),104283.0) -> 104283 | C32: =IFERROR(__xludf.DUMMYFUNCTION("""COMPUTED_VALUE"""),"PO31217") -> PO31217 | D32: =IFERROR(__xludf.DUMMYFUNCTION("""COMPUTED_VALUE"""),45367.0) -> 45367 | E32: =IFERROR(__xludf.DUMMYFUNCTION("""COMPUTED_VALUE"""),4.0) -> 4
A33: 25 | B33: =IFERROR(__xludf.DUMMYFUNCTION("""COMPUTED_VALUE"""),104202.0) -> 104202 | C33: =IFERROR(__xludf.DUMMYFUNCTION("""COMPUTED_VALUE"""),"PO31241") -> PO31241 | D33: =IFERROR(__xludf.DUMMYFUNCTION("""COMPUTED_VALUE"""),45367.0) -> 45367 | E33: =IFERROR(__xludf.DUMMYFUNCTION("""COMPUTED_VALUE"""),5.0) -> 5
A34: 26 | B34: =IFERROR(__xludf.DUMMYFUNCTION("""COMPUTED_VALUE"""),104280.0) -> 104280 | C34: =IFERROR(__xludf.DUMMYFUNCTION("""COMPUTED_VALUE"""),"PO31204") -> PO31204 | D34: =IFERROR(__xludf.DUMMYFUNCTION("""COMPUTED_VALUE"""),45367.0) -> 45367 | E34: =IFERROR(__xludf.DUMMYFUNCTION("""COMPUTED_VALUE"""),4.75) -> 4.75
A35: 27 | B35: =IFERROR(__xludf.DUMMYFUNCTION("""COMPUTED_VALUE"""),104320.0) -> 104320 | C35: =IFERROR(__xludf.DUMMYFUNCTION("""COMPUTED_VALUE"""),"PO#0681") -> PO#0681 | D35: =IFERROR(__xludf.DUMMYFUNCTION("""COMPUTED_VALUE"""),45370.0) -> 45370 | E35: =IFERROR(__xludf.DUMMYFUNCTION("""COMPUTED_VALUE"""),4.3999999999999995) -> 4.4
A36: 28 | B36: =IFERROR(__xludf.DUMMYFUNCTION("""COMPUTED_VALUE"""),104299.0) -> 104299 | C36: =IFERROR(__xludf.DUMMYFUNCTION("""COMPUTED_VALUE"""),"PO31222") -> PO31222 | D36: =IFERROR(__xludf.DUMMYFUNCTION("""COMPUTED_VALUE"""),45370.0) -> 45370 | E36: =IFERROR(__xludf.DUMMYFUNCTION("""COMPUTED_VALUE"""),4.833333333333333) -> 4.8333333
A37: 29 | B37: =IFERROR(__xludf.DUMMYFUNCTION("""COMPUTED_VALUE"""),104263.0) -> 104263 | C37: =IFERROR(__xludf.DUMMYFUNCTION("""COMPUTED_VALUE"""),"PO31221") -> PO31221 | D37: =IFERROR(__xludf.DUMMYFUNCTION("""COMPUTED_VALUE"""),45370.0) -> 45370 | E37: =IFERROR(__xludf.DUMMYFUNCTION("""COMPUTED_VALUE"""),4.325) -> 4.325
A38: 30 | B38: =IFERROR(__xludf.DUMMYFUNCTION("""COMPUTED_VALUE"""),104335.0) -> 104335 | C38: =IFERROR(__xludf.DUMMYFUNCTION("""COMPUTED_VALUE"""),"PO31228") -> PO31228 | D38: =IFERROR(__xludf.DUMMYFUNCTION("""COMPUTED_VALUE"""),45370.0) -> 45370 | E38: =IFERROR(__xludf.DUMMYFUNCTION("""COMPUTED_VALUE"""),4.75) -> 4.75
A39: 31 | B39: =IFERROR(__xludf.DUMMYFUNCTION("""COMPUTED_VALUE"""),104274.0) -> 104274 | C39: =IFERROR(__xludf.DUMMYFUNCTION("""COMPUTED_VALUE"""),"PO31219") -> PO31219 | D39: =IFERROR(__xludf.DUMMYFUNCTION("""COMPUTED_VALUE"""),45373.0) -> 45373 | E39: =IFERROR(__xludf.DUMMYFUNCTION("""COMPUTED_VALUE"""),4.166666666666667) -> 4.1666667
A40: 32 | B40: =IFERROR(__xludf.DUMMYFUNCTION("""COMPUTED_VALUE"""),104266.0) -> 104266 | C40: =IFERROR(__xludf.DUMMYFUNCTION("""COMPUTED_VALUE"""),"PO31220") -> PO31220 | D40: =IFERROR(__xludf.DUMMYFUNCTION("""COMPUTED_VALUE"""),45373.0) -> 45373 | E40: =IFERROR(__xludf.DUMMYFUNCTION("""COMPUTED_VALUE"""),4.0) -> 4
A41: 33 | B41: =IFERROR(__xludf.DUMMYFUNCTION("""COMPUTED_VALUE"""),104293.0) -> 104293 | C41: =IFERROR(__xludf.DUMMYFUNCTION("""COMPUTED_VALUE"""),"PO#0680") -> PO#0680 | D41: =IFERROR(__xludf.DUMMYFUNCTION("""COMPUTED_VALUE"""),45373.0) -> 45373 | E41: =IFERROR(__xludf.DUMMYFUNCTION("""COMPUTED_VALUE"""),4.833333333333333) -> 4.8333333
A42: 34 | B42: =IFERROR(__xludf.DUMMYFUNCTION("""COMPUTED_VALUE"""),104332.0) -> 104332 | C42: =IFERROR(__xludf.DUMMYFUNCTION("""COMPUTED_VALUE"""),"PO31229") -> PO31229 | D42: =IFERROR(__xludf.DUMMYFUNCTION("""COMPUTED_VALUE"""),45373.0) -> 45373 | E42: =IFERROR(__xludf.DUMMYFUNCTION("""COMPUTED_VALUE"""),4.75) -> 4.75
A43: 35 | B43: =IFERROR(__xludf.DUMMYFUNCTION("""COMPUTED_VALUE"""),104313.0) -> 104313 | C43: =IFERROR(__xludf.DUMMYFUNCTION("""COMPUTED_VALUE"""),"PO31245") -> PO31245 | D43: =IFERROR(__xludf.DUMMYFUNCTION("""COMPUTED_VALUE"""),45374.0) -> 45374 | E43: =IFERROR(__xludf.DUMMYFUNCTION("""COMPUTED_VALUE"""),4.3999999999999995) -> 4.4
...

Sheet raw report
A3: 2024-2025 | E3: 2023-2024 | I3: 2022-2023 | M3: 2022-2023 | Q3: 2023-2024 | U3: 2024-2025 | Y3: 2022-2023 | AB3: 2023-2024 | AE3: 2024-2025
C4: Averagt Ratings | G4: Averagt Ratings | K4: Averagt Ratings | Y4: =IFERROR(__xludf.DUMMYFUNCTION("QUERY(M:N, ""select M, AVG(N) where M is not null group by M label AVG(N) 'Average Rating'"", 0)"),"") | Z4: =IFERROR(__xludf.DUMMYFUNCTION("""COMPUTED_VALUE"""),"Average Rating") -> Average Rating | AB4: =IFERROR(__xludf.DUMMYFUNCTION("QUERY(Q:R, ""select Q, AVG(R) where Q is not null group by Q label AVG(R) 'Average Rating'"", 0)"),"") | AC4: =IFERROR(__xludf.DUMMYFUNCTION("""COMPUTED_VALUE"""),"Average Rating") -> Average Rating | AE4: =IFERROR(__xludf.DUMMYFUNCTION("QUERY(U:V, ""select U, AVG(V) where U is not null group by U label AVG(V) 'Average Rating'"", 0)"),"") | AF4: =IFERROR(__xludf.DUMMYFUNCTION("""COMPUTED_VALUE"""),"Average Rating") -> Average Rating
B5: Company Name | F5: Company Name | I5: COMPANY | K5: =average(K6:K9) -> 4.7751923 | M5: =IFERROR(__xludf.DUMMYFUNCTION("FILTER( {DATABASE!E2:E1099, DATABASE!AC2:AC1099, DATABASE!D2:D1099}, (DATABASE!D2:D1099 >= DATE(2022,7,1)) * (DATABASE!D2:D1099 <= DATE(2023,6,30)) )"),"EIG Metal Engravers") -> EIG Metal Engravers | N5: =IFERROR(__xludf.DUMMYFUNCTION("""COMPUTED_VALUE"""),4.0) -> 4 | O5: =IFERROR(__xludf.DUMMYFUNCTION("""COMPUTED_VALUE"""),44746.0) -> 44746 | Q5: =IFERROR(__xludf.DUMMYFUNCTION("FILTER( {DATABASE!E2:E1099, DATABASE!AC2:AC1099, DATABASE!D2:D1099}, (DATABASE!D2:D1099 >= DATE(2023,7,1)) * (DATABASE!D2:D1099 <= DATE(2024,6,30)) )"),"Leonard Prints Inc.") -> Leonard Prints Inc. | R5: =IFERROR(__xludf.DUMMYFUNCTION("""COMPUTED_VALUE"""),4.833333333333333) -> 4.8333333 | S5: =IFERROR(__xludf.DUMMYFUNCTION("""COMPUTED_VALUE"""),45110.0) -> 45110 | U5: =IFERROR(__xludf.DUMMYFUNCTION("FILTER( {DATABASE!E2:E1099, DATABASE!AC2:AC1099, DATABASE!D2:D1099}, (DATABASE!D2:D1099 >= DATE(2024,7,1)) * (DATABASE!D2:D1099 <= DATE(2025,6,30)) )"),"Creative Juice Digital Printing") -> Creative Juice Digital Printing | V5: =IFERROR(__xludf.DUMMYFUNCTION("""COMPUTED_VALUE"""),4.833333333333333) -> 4.8333333 | W5: =IFERROR(__xludf.DUMMYFUNCTION("""COMPUTED_VALUE"""),45476.0) -> 45476 | Y5: =IFERROR(__xludf.DUMMYFUNCTION("""COMPUTED_VALUE"""),"2022-2023") -> 2022-2023 | AB5: =IFERROR(__xludf.DUMMYFUNCTION("""COMPUTED_VALUE"""),"2023-2024") -> 2023-2024 | AE5: =IFERROR(__xludf.DUMMYFUNCTION("""COMPUTED_VALUE"""),"2024-2025") -> 2024-2025
A6: Books | C6: =average(C7:C12) -> #DIV/0! | E6: Books | G6: =average(G7:G12) -> 4.83125 | I6: Advertisement Printing | M6: =IFERROR(__xludf.DUMMYFUNCTION("""COMPUTED_VALUE"""),"Atlas Superflags") -> Atlas Superflags | N6: =IFERROR(__xludf.DUMMYFUNCTION("""COMPUTED_VALUE"""),5.0) -> 5 | O6: =IFERROR(__xludf.DUMMYFUNCTION("""COMPUTED_VALUE"""),44750.0) -> 44750 | Q6: =IFERROR(__xludf.DUMMYFUNCTION("""COMPUTED_VALUE"""),"Leonard Prints Inc.") -> Leonard Prints Inc. | R6: =IFERROR(__xludf.DUMMYFUNCTION("""COMPUTED_VALUE"""),4.833333333333333) -> 4.8333333 | S6: =IFERROR(__xludf.DUMMYFUNCTION("""COMPUTED_VALUE"""),45110.0) -> 45110 | U6: =IFERROR(__xludf.DUMMYFUNCTION("""COMPUTED_VALUE"""),"Arkin Hardware") -> Arkin Hardware | V6: =IFERROR(__xludf.DUMMYFUNCTION("""COMPUTED_VALUE"""),4.625) -> 4.625 | W6: =IFERROR(__xludf.DUMMYFUNCTION("""COMPUTED_VALUE"""),45477.0) -> 45477 | Y6: =IFERROR(__xludf.DUMMYFUNCTION("""COMPUTED_VALUE"""),"Abenson Ventures, Inc.") -> Abenson Ventures, Inc. | Z6: =IFERROR(__xludf.DUMMYFUNCTION("""COMPUTED_VALUE"""),4.916666666666666) -> 4.9166667 | AB6: =IFERROR(__xludf.DUMMYFUNCTION("""COMPUTED_VALUE"""),"ADBM Lightning Equipment Trading") -> ADBM Lightning Equipment Trading | AC6: =IFERROR(__xludf.DUMMYFUNCTION("""COMPUTED_VALUE"""),5.0) -> 5 | AE6: =IFERROR(__xludf.DUMMYFUNCTION("""COMPUTED_VALUE"""),"4David's Book Trading") -> 4David's Book Trading | AF6: =IFERROR(__xludf.DUMMYFUNCTION("""COMPUTED_VALUE"""),4.803333333333333) -> 4.8033333
A7: 1 | B7: REX Book Store | E7: 1 | F7: REX Book Store | G7: 4.8333333 | I7: 1 | J7: Creative Juice Digital Printing | K7: 4.7751923 | M7: =IFERROR(__xludf.DUMMYFUNCTION("""COMPUTED_VALUE"""),"Atlas Superflags") -> Atlas Superflags | N7: =IFERROR(__xludf.DUMMYFUNCTION("""COMPUTED_VALUE"""),4.066666666666666) -> 4.0666667 | O7: =IFERROR(__xludf.DUMMYFUNCTION("""COMPUTED_VALUE"""),44750.0) -> 44750 | Q7: =IFERROR(__xludf.DUMMYFUNCTION("""COMPUTED_VALUE"""),"Net Ad IT Solutions") -> Net Ad IT Solutions | R7: =IFERROR(__xludf.DUMMYFUNCTION("""COMPUTED_VALUE"""),4.733333333333333) -> 4.7333333 | S7: =IFERROR(__xludf.DUMMYFUNCTION("""COMPUTED_VALUE"""),45127.0) -> 45127 | U7: =IFERROR(__xludf.DUMMYFUNCTION("""COMPUTED_VALUE"""),"EIG Metal Engravers") -> EIG Metal Engravers | V7: =IFERROR(__xludf.DUMMYFUNCTION("""COMPUTED_VALUE"""),5.0) -> 5 | W7: =IFERROR(__xludf.DUMMYFUNCTION("""COMPUTED_VALUE"""),45478.0) -> 45478 | Y7: =IFERROR(__xludf.DUMMYFUNCTION("""COMPUTED_VALUE"""),"Ahrcel's Gift Shop") -> Ahrcel's Gift Shop | Z7: =IFERROR(__xludf.DUMMYFUNCTION("""COMPUTED_VALUE"""),5.0) -> 5 | AB7: =IFERROR(__xludf.DUMMYFUNCTION("""COMPUTED_VALUE"""),"Abacus Book & Card Corp.") -> Abacus Book & Card Corp. | AC7: =IFERROR(__xludf.DUMMYFUNCTION("""COMPUTED_VALUE"""),4.845897435897436) -> 4.8458974 | AE7: =IFERROR(__xludf.DUMMYFUNCTION("""COMPUTED_VALUE"""),"888 Tile Phil Corp") -> 888 Tile Phil Corp | AF7: =IFERROR(__xludf.DUMMYFUNCTION("""COMPUTED_VALUE"""),4.416666666666667) -> 4.4166667
A8: 2 | B8: BELVIEW CO., INC. | E8: 2 | F8: BELVIEW CO., INC. | G8: 4.7583333 | I8: 2 | J8: Luneta Advertisement Inc. | M8: =IFERROR(__xludf.DUMMYFUNCTION("""COMPUTED_VALUE"""),"Marguerita Maria Nina I. Kanapi") -> Marguerita Maria Nina I. Kanapi | N8: =IFERROR(__xludf.DUMMYFUNCTION("""COMPUTED_VALUE"""),5.0) -> 5 | O8: =IFERROR(__xludf.DUMMYFUNCTION("""COMPUTED_VALUE"""),44756.0) -> 44756 | Q8: =IFERROR(__xludf.DUMMYFUNCTION("""COMPUTED_VALUE"""),"Forefront Book Co., Inc.") -> Forefront Book Co., Inc. | R8: =IFERROR(__xludf.DUMMYFUNCTION("""COMPUTED_VALUE"""),4.733333333333333) -> 4.7333333 | S8: =IFERROR(__xludf.DUMMYFUNCTION("""COMPUTED_VALUE"""),45128.0) -> 45128 | U8: =IFERROR(__xludf.DUMMYFUNCTION("""COMPUTED_VALUE"""),"Arkin Hardware") -> Arkin Hardware | V8: =IFERROR(__xludf.DUMMYFUNCTION("""COMPUTED_VALUE"""),4.625) -> 4.625 | W8: =IFERROR(__xludf.DUMMYFUNCTION("""COMPUTED_VALUE"""),45481.0) -> 45481 | Y8: =IFERROR(__xludf.DUMMYFUNCTION("""COMPUTED_VALUE"""),"Alpha-Cored Technology Systems, Inc.") -> Alpha-Cored Technology Systems, Inc. | Z8: =IFERROR(__xludf.DUMMYFUNCTION("""COMPUTED_VALUE"""),5.0) -> 5 | AB8: =IFERROR(__xludf.DUMMYFUNCTION("""COMPUTED_VALUE"""),"Abenson Ventures, Inc.") -> Abenson Ventures, Inc. | AC8: =IFERROR(__xludf.DUMMYFUNCTION("""COMPUTED_VALUE"""),4.608333333333333) -> 4.6083333 | AE8: =IFERROR(__xludf.DUMMYFUNCTION("""COMPUTED_VALUE"""),"Abacus Book & Card Corp.") -> Abacus Book & Card Corp. | AF8: =IFERROR(__xludf.DUMMYFUNCTION("""COMPUTED_VALUE"""),4.805555555555555) -> 4.8055556
A9: 3 | B9: CD Books International, Inc. | E9: 3 | F9: CD Books International, Inc. | I9: 3 | J9: Doo Graphic Services | M9: =IFERROR(__xludf.DUMMYFUNCTION("""COMPUTED_VALUE"""),"Hospeco Philippines, Inc.") -> Hospeco Philippines, Inc. | N9: =IFERROR(__xludf.DUMMYFUNCTION("""COMPUTED_VALUE"""),4.533333333333333) -> 4.5333333 | O9: =IFERROR(__xludf.DUMMYFUNCTION("""COMPUTED_VALUE"""),44757.0) -> 44757 | Q9: =IFERROR(__xludf.DUMMYFUNCTION("""COMPUTED_VALUE"""),"Contrade Integrated Depot") -> Contrade Integrated Depot | R9: =IFERROR(__xludf.DUMMYFUNCTION("""COMPUTED_VALUE"""),4.680000000000001) -> 4.68 | S9: =IFERROR(__xludf.DUMMYFUNCTION("""COMPUTED_VALUE"""),45131.0) -> 45131 | U9: =IFERROR(__xludf.DUMMYFUNCTION("""COMPUTED_VALUE"""),"Abiva Publishing House, Inc.") -> Abiva Publishing House, Inc. | V9: =IFERROR(__xludf.DUMMYFUNCTION("""COMPUTED_VALUE"""),4.833333333333333) -> 4.8333333 | W9: =IFERROR(__xludf.DUMMYFUNCTION("""COMPUTED_VALUE"""),45484.0) -> 45484 | Y9: =IFERROR(__xludf.DUMMYFUNCTION("""COMPUTED_VALUE"""),"Amalgamated Specialties Corporation") -> Amalgamated Specialties Corporation | Z9: =IFERROR(__xludf.DUMMYFUNCTION("""COMPUTED_VALUE"""),4.333333333333333) -> 4.3333333 | AB9: =IFERROR(__xludf.DUMMYFUNCTION("""COMPUTED_VALUE"""),"Ahrcel's Gift Shop") -> Ahrcel's Gift Shop | AC9: =IFERROR(__xludf.DUMMYFUNCTION("""COMPUTED_VALUE"""),4.836111111111111) -> 4.8361111 | AE9: =IFERROR(__xludf.DUMMYFUNCTION("""COMPUTED_VALUE"""),"Abenson Ventures, Inc.") -> Abenson Ventures, Inc. | AF9: =IFERROR(__xludf.DUMMYFUNCTION("""COMPUTED_VALUE"""),4.8973958333333325) -> 4.8973958
A10: 4 | B10: Forefront Book Co | E10: 4 | F10: Forefront Book Co | G10: 4.7333333 | I10: Audio Visual and Equipment | K10: =average(K11:K14) -> #DIV/0! | M10: =IFERROR(__xludf.DUMMYFUNCTION("""COMPUTED_VALUE"""),"Oray Copier Solutions") -> Oray Copier Solutions | N10: =IFERROR(__xludf.DUMMYFUNCTION("""COMPUTED_VALUE"""),5.0) -> 5 | O10: =IFERROR(__xludf.DUMMYFUNCTION("""COMPUTED_VALUE"""),44757.0) -> 44757 | Q10: =IFERROR(__xludf.DUMMYFUNCTION("""COMPUTED_VALUE"""),"Alpha-Cored Technology Systems, Inc.") -> Alpha-Cored Technology Systems, Inc. | R10: =IFERROR(__xludf.DUMMYFUNCTION("""COMPUTED_VALUE"""),5.0) -> 5 | S10: =IFERROR(__xludf.DUMMYFUNCTION("""COMPUTED_VALUE"""),45134.0) -> 45134 | U10: =IFERROR(__xludf.DUMMYFUNCTION("""COMPUTED_VALUE"""),"Mostaco Printing") -> Mostaco Printing | V10: =IFERROR(__xludf.DUMMYFUNCTION("""COMPUTED_VALUE"""),4.833333333333333) -> 4.8333333 | W10: =IFERROR(__xludf.DUMMYFUNCTION("""COMPUTED_VALUE"""),45492.0) -> 45492 | Y10: =IFERROR(__xludf.DUMMYFUNCTION("""COMPUTED_VALUE"""),"Amazon") -> Amazon | Z10: =IFERROR(__xludf.DUMMYFUNCTION("""COMPUTED_VALUE"""),4.708) -> 4.708 | AB10: =IFERROR(__xludf.DUMMYFUNCTION("""COMPUTED_VALUE"""),"Alpha Steel Office and Home Furnishing Company") -> Alpha Steel Office and Home Furnishing Company | AC10: =IFERROR(__xludf.DUMMYFUNCTION("""COMPUTED_VALUE"""),5.0) -> 5 | AE10: =IFERROR(__xludf.DUMMYFUNCTION("""COMPUTED_VALUE"""),"Abiva Publishing House, Inc.") -> Abiva Publishing House, Inc. | AF10: =IFERROR(__xludf.DUMMYFUNCTION("""COMPUTED_VALUE"""),4.833333333333333) -> 4.8333333
A11: 5 | B11: Phoenix Publishing House | E11: 5 | F11: Phoenix Publishing House | I11: 4 | J11: Lovell de Mesa | M11: =IFERROR(__xludf.DUMMYFUNCTION("""COMPUTED_VALUE"""),"Amazon") -> Amazon | N11: =IFERROR(__xludf.DUMMYFUNCTION("""COMPUTED_VALUE"""),4.3116666666666665) -> 4.3116667 | O11: =IFERROR(__xludf.DUMMYFUNCTION("""COMPUTED_VALUE"""),44762.0) -> 44762 | Q11: =IFERROR(__xludf.DUMMYFUNCTION("""COMPUTED_VALUE"""),"Tropical Palms Fashion House, Inc.") -> Tropical Palms Fashion House, Inc. | R11: =IFERROR(__xludf.DUMMYFUNCTION("""COMPUTED_VALUE"""),4.608333333333333) -> 4.6083333 | S11: =IFERROR(__xludf.DUMMYFUNCTION("""COMPUTED_VALUE"""),45140.0) -> 45140 | U11: =IFERROR(__xludf.DUMMYFUNCTION("""COMPUTED_VALUE"""),"CD Books International, Inc.") -> CD Books International, Inc. | V11: =IFERROR(__xludf.DUMMYFUNCTION("""COMPUTED_VALUE"""),4.833333333333333) -> 4.8333333 | W11: =IFERROR(__xludf.DUMMYFUNCTION("""COMPUTED_VALUE"""),45492.0) -> 45492 | Y11: =IFERROR(__xludf.DUMMYFUNCTION("""COMPUTED_VALUE"""),"Arkwood Plus Fine Furniture") -> Arkwood Plus Fine Furniture | Z11: =IFERROR(__xludf.DUMMYFUNCTION("""COMPUTED_VALUE"""),4.0) -> 4 | AB11: =IFERROR(__xludf.DUMMYFUNCTION("""COMPUTED_VALUE"""),"Alpha-Cored Technology Systems, Inc.") -> Alpha-Cored Technology Systems, Inc. | AC11: =IFERROR(__xludf.DUMMYFUNCTION("""COMPUTED_VALUE"""),5.0) -> 5 | AE11: =IFERROR(__xludf.DUMMYFUNCTION("""COMPUTED_VALUE"""),"Ace Hardware") -> Ace Hardware | AF11: =IFERROR(__xludf.DUMMYFUNCTION("""COMPUTED_VALUE"""),4.791666666666667) -> 4.7916667
A12: 6 | B12: Booktrends Enterprises | E12: 6 | F12: Booktrends Enterprises | G12: 5 | I12: Books | K12: =average(K13:K21) -> #DIV/0! | M12: =IFERROR(__xludf.DUMMYFUNCTION("""COMPUTED_VALUE"""),"Contrade Integrated Depot") -> Contrade Integrated Depot | N12: =IFERROR(__xludf.DUMMYFUNCTION("""COMPUTED_VALUE"""),3.9166666666666665) -> 3.9166667 | O12: =IFERROR(__xludf.DUMMYFUNCTION("""COMPUTED_VALUE"""),44763.0) -> 44763 | Q12: =IFERROR(__xludf.DUMMYFUNCTION("""COMPUTED_VALUE"""),"Awardextremes, Inc.") -> Awardextremes, Inc. | R12: =IFERROR(__xludf.DUMMYFUNCTION("""COMPUTED_VALUE"""),4.566666666666666) -> 4.5666667 | S12: =IFERROR(__xludf.DUMMYFUNCTION("""COMPUTED_VALUE"""),45141.0) -> 45141 | U12: =IFERROR(__xludf.DUMMYFUNCTION("""COMPUTED_VALUE"""),"Belview Co., Inc.") -> Belview Co., Inc. | V12: =IFERROR(__xludf.DUMMYFUNCTION("""COMPUTED_VALUE"""),4.833333333333333) -> 4.8333333 | W12: =IFERROR(__xludf.DUMMYFUNCTION("""COMPUTED_VALUE"""),45492.0) -> 45492 | Y12: =IFERROR(__xludf.DUMMYFUNCTION("""COMPUTED_VALUE"""),"Atlas Superflags") -> Atlas Superflags | Z12: =IFERROR(__xludf.DUMMYFUNCTION("""COMPUTED_VALUE"""),4.766666666666667) -> 4.7666667 | AB12: =IFERROR(__xludf.DUMMYFUNCTION("""COMPUTED_VALUE"""),"Amalgamated Specialties Corporation") -> Amalgamated Specialties Corporation | AC12: =IFERROR(__xludf.DUMMYFUNCTION("""COMPUTED_VALUE"""),5.0) -> 5 | AE12: =IFERROR(__xludf.DUMMYFUNCTION("""COMPUTED_VALUE"""),"Alpha Steel Office and Home Furnishing Company") -> Alpha Steel Office and Home Furnishing Company | AF12: =IFERROR(__xludf.DUMMYFUNCTION("""COMPUTED_VALUE"""),4.833333333333333) -> 4.8333333
A13: Cleaning Materials | C13: =average(C14:C15) -> 4.6809896 | E13: School/Office Supplies | G13: =average(G14:G21) -> 4.7778378 | I13: 5 | J13: C & E Publishing Inc | M13: =IFERROR(__xludf.DUMMYFUNCTION("""COMPUTED_VALUE"""),"Rivchem Enterprises") -> Rivchem Enterprises | N13: =IFERROR(__xludf.DUMMYFUNCTION("""COMPUTED_VALUE"""),4.833333333333333) -> 4.8333333 | O13: =IFERROR(__xludf.DUMMYFUNCTION("""COMPUTED_VALUE"""),44763.0) -> 44763 | Q13: =IFERROR(__xludf.DUMMYFUNCTION("""COMPUTED_VALUE"""),"Contrade Integrated Depot") -> Contrade Integrated Depot | R13: =IFERROR(__xludf.DUMMYFUNCTION("""COMPUTED_VALUE"""),4.566666666666666) -> 4.5666667 | S13: =IFERROR(__xludf.DUMMYFUNCTION("""COMPUTED_VALUE"""),45142.0) -> 45142 | U13: =IFERROR(__xludf.DUMMYFUNCTION("""COMPUTED_VALUE"""),"Belview Co., Inc.") -> Belview Co., Inc. | V13: =IFERROR(__xludf.DUMMYFUNCTION("""COMPUTED_VALUE"""),4.833333333333333) -> 4.8333333 | W13: =IFERROR(__xludf.DUMMYFUNCTION("""COMPUTED_VALUE"""),45492.0) -> 45492 | Y13: =IFERROR(__xludf.DUMMYFUNCTION("""COMPUTED_VALUE"""),"Awardextremes, Inc.") -> Awardextremes, Inc. | Z13: =IFERROR(__xludf.DUMMYFUNCTION("""COMPUTED_VALUE"""),4.666666666666667) -> 4.6666667 | AB13: =IFERROR(__xludf.DUMMYFUNCTION("""COMPUTED_VALUE"""),"Arkin Hardware") -> Arkin Hardware | AC13: =IFERROR(__xludf.DUMMYFUNCTION("""COMPUTED_VALUE"""),4.4714285714285715) -> 4.4714286 | AE13: =IFERROR(__xludf.DUMMYFUNCTION("""COMPUTED_VALUE"""),"Alpha-Cored Technology Systems, Inc.") -> Alpha-Cored Technology Systems, Inc. | AF13: =IFERROR(__xludf.DUMMYFUNCTION("""COMPUTED_VALUE"""),4.925925925925926) -> 4.9259259
A14: 7 | B14: Rivchem Enterprises | C14: 4.7161458 | E14: 7 | F14: Abacus Book and Card Corporation | G14: 4.8458974 | I14: 6 | J14: National Book Store, Inc | M14: =IFERROR(__xludf.DUMMYFUNCTION("""COMPUTED_VALUE"""),"Belview Co., Inc.") -> Belview Co., Inc. | N14: =IFERROR(__xludf.DUMMYFUNCTION("""COMPUTED_VALUE"""),5.0) -> 5 | O14: =IFERROR(__xludf.DUMMYFUNCTION("""COMPUTED_VALUE"""),44764.0) -> 44764 | Q14: =IFERROR(__xludf.DUMMYFUNCTION("""COMPUTED_VALUE"""),"Lordfel Marketing") -> Lordfel Marketing | R14: =IFERROR(__xludf.DUMMYFUNCTION("""COMPUTED_VALUE"""),4.0) -> 4 | S14: =IFERROR(__xludf.DUMMYFUNCTION("""COMPUTED_VALUE"""),45142.0) -> 45142 | U14: =IFERROR(__xludf.DUMMYFUNCTION("""COMPUTED_VALUE"""),"Contrade Integrated Depot") -> Contrade Integrated Depot | V14: =IFERROR(__xludf.DUMMYFUNCTION("""COMPUTED_VALUE"""),4.583333333333333) -> 4.5833333 | W14: =IFERROR(__xludf.DUMMYFUNCTION("""COMPUTED_VALUE"""),45493.0) -> 45493 | Y14: =IFERROR(__xludf.DUMMYFUNCTION("""COMPUTED_VALUE"""),"Belview Co., Inc.") -> Belview Co., Inc. | Z14: =IFERROR(__xludf.DUMMYFUNCTION("""COMPUTED_VALUE"""),5.0) -> 5 | AB14: =IFERROR(__xludf.DUMMYFUNCTION("""COMPUTED_VALUE"""),"Atlas Superflags") -> Atlas Superflags | AC14: =IFERROR(__xludf.DUMMYFUNCTION("""COMPUTED_VALUE"""),4.0) -> 4 | AE14: =IFERROR(__xludf.DUMMYFUNCTION("""COMPUTED_VALUE"""),"Arkin Hardware") -> Arkin Hardware | AF14: =IFERROR(__xludf.DUMMYFUNCTION("""COMPUTED_VALUE"""),4.867222222222223) -> 4.8672222
A15: 8 | B15: Chemtrust Global Market | C15: 4.6458333 | E15: 8 | F15: Contrade Integrated Depot, Inc, | G15: 4.6089167 | I15: 7 | J15: Rex Bookstore | M15: =IFERROR(__xludf.DUMMYFUNCTION("""COMPUTED_VALUE"""),"Belview Co., Inc.") -> Belview Co., Inc. | N15: =IFERROR(__xludf.DUMMYFUNCTION("""COMPUTED_VALUE"""),5.0) -> 5 | O15: =IFERROR(__xludf.DUMMYFUNCTION("""COMPUTED_VALUE"""),44764.0) -> 44764 | Q15: =IFERROR(__xludf.DUMMYFUNCTION("""COMPUTED_VALUE"""),"Rivchem Enterprises") -> Rivchem Enterprises | R15: =IFERROR(__xludf.DUMMYFUNCTION("""COMPUTED_VALUE"""),4.6) -> 4.6 | S15: =IFERROR(__xludf.DUMMYFUNCTION("""COMPUTED_VALUE"""),45145.0) -> 45145 | U15: =IFERROR(__xludf.DUMMYFUNCTION("""COMPUTED_VALUE"""),"Javammp Printing Services") -> Javammp Printing Services | V15: =IFERROR(__xludf.DUMMYFUNCTION("""COMPUTED_VALUE"""),3.9166666666666665) -> 3.9166667 | W15: =IFERROR(__xludf.DUMMYFUNCTION("""COMPUTED_VALUE"""),45495.0) -> 45495 | Y15: =IFERROR(__xludf.DUMMYFUNCTION("""COMPUTED_VALUE"""),"Brown Movement for Cultural Advancement, Inc.") -> Brown Movement for Cultural Advancement, Inc. | Z15: =IFERROR(__xludf.DUMMYFUNCTION("""COMPUTED_VALUE"""),5.0) -> 5 | AB15: =IFERROR(__xludf.DUMMYFUNCTION("""COMPUTED_VALUE"""),"Awardextremes, Inc.") -> Awardextremes, Inc. | AC15: =IFERROR(__xludf.DUMMYFUNCTION("""COMPUTED_VALUE"""),4.566666666666666) -> 4.5666667 | AE15: =IFERROR(__xludf.DUMMYFUNCTION("""COMPUTED_VALUE"""),"Asahl Design Centre Inc.") -> Asahl Design Centre Inc. | AF15: =IFERROR(__xludf.DUMMYFUNCTION("""COMPUTED_VALUE"""),4.858333333333333) -> 4.8583333
A16: School/Office Supplies | C16: =average(C17:C26) -> 4.7827932 | E16: 9 | F16: Times Trading Co., Inc. | G16: 4.6860417 | I16: 8 | J16: Phoenix Publishing House | M16: =IFERROR(__xludf.DUMMYFUNCTION("""COMPUTED_VALUE"""),"Amalgamated Specialties Corporation") -> Amalgamated Specialties Corporation | N16: =IFERROR(__xludf.DUMMYFUNCTION("""COMPUTED_VALUE"""),4.333333333333333) -> 4.3333333 | O16: =IFERROR(__xludf.DUMMYFUNCTION("""COMPUTED_VALUE"""),44767.0) -> 44767 | Q16: =IFERROR(__xludf.DUMMYFUNCTION("""COMPUTED_VALUE"""),"Rivchem Enterprises") -> Rivchem Enterprises | R16: =IFERROR(__xludf.DUMMYFUNCTION("""COMPUTED_VALUE"""),4.6) -> 4.6 | S16: =IFERROR(__xludf.DUMMYFUNCTION("""COMPUTED_VALUE"""),45146.0) -> 45146 | U16: =IFERROR(__xludf.DUMMYFUNCTION("""COMPUTED_VALUE"""),"BIG LEAGUE SPORTS WEAR SHOP. INC.") -> BIG LEAGUE SPORTS WEAR SHOP. INC. | V16: =IFERROR(__xludf.DUMMYFUNCTION("""COMPUTED_VALUE"""),4.0) -> 4 | W16: =IFERROR(__xludf.DUMMYFUNCTION("""COMPUTED_VALUE"""),45503.0) -> 45503 | Y16: =IFERROR(__xludf.DUMMYFUNCTION("""COMPUTED_VALUE"""),"Chemtrust Global Market, Inc.") -> Chemtrust Global Market, Inc. | Z16: =IFERROR(__xludf.DUMMYFUNCTION("""COMPUTED_VALUE"""),4.066666666666666) -> 4.0666667 | AB16: =IFERROR(__xludf.DUMMYFUNCTION("""COMPUTED_VALUE"""),"Belview Co., Inc.") -> Belview Co., Inc. | AC16: =IFERROR(__xludf.DUMMYFUNCTION("""COMPUTED_VALUE"""),4.753333333333333) -> 4.7533333 | AE16: =IFERROR(__xludf.DUMMYFUNCTION("""COMPUTED_VALUE"""),"Atlas Superflags") -> Atlas Superflags | AF16: =IFERROR(__xludf.DUMMYFUNCTION("""COMPUTED_VALUE"""),4.7444444444444445) -> 4.7444444
A17: 9 | B17: Abacus Book and Card Corporation | C17: 4.7222222 | E17: 10 | F17: Paper Tree Marketing Group, Inc. | I17: 9 | J17: F & J De Jesus, Inc | M17: =IFERROR(__xludf.DUMMYFUNCTION("""COMPUTED_VALUE"""),"Contrade Integrated Depot") -> Contrade Integrated Depot | N17: =IFERROR(__xludf.DUMMYFUNCTION("""COMPUTED_VALUE"""),3.6) -> 3.6 | O17: =IFERROR(__xludf.DUMMYFUNCTION("""COMPUTED_VALUE"""),44767.0) -> 44767 | Q17: =IFERROR(__xludf.DUMMYFUNCTION("""COMPUTED_VALUE"""),"Lordfel Marketing") -> Lordfel Marketing | R17: =IFERROR(__xludf.DUMMYFUNCTION("""COMPUTED_VALUE"""),5.0) -> 5 | S17: =IFERROR(__xludf.DUMMYFUNCTION("""COMPUTED_VALUE"""),45149.0) -> 45149 | U17: =IFERROR(__xludf.DUMMYFUNCTION("""COMPUTED_VALUE"""),"Printing Shop PrintPilipinas.com") -> Printing Shop PrintPilipinas.com | V17: =IFERROR(__xludf.DUMMYFUNCTION("""COMPUTED_VALUE"""),4.833333333333333) -> 4.8333333 | W17: =IFERROR(__xludf.DUMMYFUNCTION("""COMPUTED_VALUE"""),45505.0) -> 45505 | Y17: =IFERROR(__xludf.DUMMYFUNCTION("""COMPUTED_VALUE"""),"Columbia Technologies, Inc.") -> Columbia Technologies, Inc. | Z17: =IFERROR(__xludf.DUMMYFUNCTION("""COMPUTED_VALUE"""),4.958333333333333) -> 4.9583333 | AB17: =IFERROR(__xludf.DUMMYFUNCTION("""COMPUTED_VALUE"""),"Beyond Global Multiales Corp.") -> Beyond Global Multiales Corp. | AC17: =IFERROR(__xludf.DUMMYFUNCTION("""COMPUTED_VALUE"""),4.833333333333333) -> 4.8333333 | AE17: =IFERROR(__xludf.DUMMYFUNCTION("""COMPUTED_VALUE"""),"BIG LEAGUE SPORTS WEAR SHOP. INC.") -> BIG LEAGUE SPORTS WEAR SHOP. INC. | AF17: =IFERROR(__xludf.DUMMYFUNCTION("""COMPUTED_VALUE"""),4.0) -> 4
A18: 10 | B18: Contrade Integrated Depot, Inc, | C18: 4.7083333 | E18: 11 | F18: EA Intertrade General Merchandising, Inc. | G18: 5 | I18: 10 | J18: BOOK TRENDS ENTERPRISES | M18: =IFERROR(__xludf.DUMMYFUNCTION("""COMPUTED_VALUE"""),"Gift Republic, Inc.") -> Gift Republic, Inc. | N18: =IFERROR(__xludf.DUMMYFUNCTION("""COMPUTED_VALUE"""),2.0) -> 2 | O18: =IFERROR(__xludf.DUMMYFUNCTION("""COMPUTED_VALUE"""),44774.0) -> 44774 | Q18: =IFERROR(__xludf.DUMMYFUNCTION("""COMPUTED_VALUE"""),"Lordfel Marketing") -> Lordfel Marketing | R18: =IFERROR(__xludf.DUMMYFUNCTION("""COMPUTED_VALUE"""),4.0) -> 4 | S18: =IFERROR(__xludf.DUMMYFUNCTION("""COMPUTED_VALUE"""),45149.0) -> 45149 | U18: =IFERROR(__xludf.DUMMYFUNCTION("""COMPUTED_VALUE"""),"Mostaco Printing") -> Mostaco Printing | V18: =IFERROR(__xludf.DUMMYFUNCTION("""COMPUTED_VALUE"""),4.75) -> 4.75 | W18: =IFERROR(__xludf.DUMMYFUNCTION("""COMPUTED_VALUE"""),45509.0) -> 45509 | Y18: =IFERROR(__xludf.DUMMYFUNCTION("""COMPUTED_VALUE"""),"Contrade Integrated Depot") -> Contrade Integrated Depot | Z18: =IFERROR(__xludf.DUMMYFUNCTION("""COMPUTED_VALUE"""),4.325444444444444) -> 4.3254444 | AB18: =IFERROR(__xludf.DUMMYFUNCTION("""COMPUTED_VALUE"""),"Booktrens Enterprises") -> Booktrens Enterprises | AC18: =IFERROR(__xludf.DUMMYFUNCTION("""COMPUTED_VALUE"""),5.0) -> 5 | AE18: =IFERROR(__xludf.DUMMYFUNCTION("""COMPUTED_VALUE"""),"Barcaman Couture Corporation") -> Barcaman Couture Corporation | AF18: =IFERROR(__xludf.DUMMYFUNCTION("""COMPUTED_VALUE"""),3.5666666666666664) -> 3.5666667
A19: 11 | B19: Times Trading Co., Inc. | C19: 4.8333333 | E19: 12 | F19: One Supply | I19: 11 | J19: CD Books International, Inc | M19: =IFERROR(__xludf.DUMMYFUNCTION("""COMPUTED_VALUE"""),"Gift Republic, Inc.") -> Gift Republic, Inc. | N19: =IFERROR(__xludf.DUMMYFUNCTION("""COMPUTED_VALUE"""),2.066666666666667) -> 2.0666667 | O19: =IFERROR(__xludf.DUMMYFUNCTION("""COMPUTED_VALUE"""),44774.0) -> 44774 | Q19: =IFERROR(__xludf.DUMMYFUNCTION("""COMPUTED_VALUE"""),"Lordfel Marketing") -> Lordfel Marketing | R19: =IFERROR(__xludf.DUMMYFUNCTION("""COMPUTED_VALUE"""),4.0) -> 4 | S19: =IFERROR(__xludf.DUMMYFUNCTION("""COMPUTED_VALUE"""),45149.0) -> 45149 | U19: =IFERROR(__xludf.DUMMYFUNCTION("""COMPUTED_VALUE"""),"Contrade Integrated Depot") -> Contrade Integrated Depot | V19: =IFERROR(__xludf.DUMMYFUNCTION("""COMPUTED_VALUE"""),4.833333333333333) -> 4.8333333 | W19: =IFERROR(__xludf.DUMMYFUNCTION("""COMPUTED_VALUE"""),45510.0) -> 45510 | Y19: =IFERROR(__xludf.DUMMYFUNCTION("""COMPUTED_VALUE"""),"Creative Juice Digital Printing") -> Creative Juice Digital Printing | Z19: =IFERROR(__xludf.DUMMYFUNCTION("""COMPUTED_VALUE"""),4.775192307692308) -> 4.7751923 | AB19: =IFERROR(__xludf.DUMMYFUNCTION("""COMPUTED_VALUE"""),"Chemtrust Global Market, Inc.") -> Chemtrust Global Market, Inc. | AC19: =IFERROR(__xludf.DUMMYFUNCTION("""COMPUTED_VALUE"""),4.794444444444444) -> 4.7944444 | AE19: =IFERROR(__xludf.DUMMYFUNCTION("""COMPUTED_VALUE"""),"Belview Co., Inc.") -> Belview Co., Inc. | AF19: =IFERROR(__xludf.DUMMYFUNCTION("""COMPUTED_VALUE"""),4.986706349206351) -> 4.9867063
A20: 12 | B20: Paper Tree Marketing Group, Inc. | C20: 4.9166667 | E20: 13 | F20: Commerce Asia Inc. | G20: 4.7483333 | I20: 12 | J20: CREATIVE MIND BOOKS CENTER | M20: =IFERROR(__xludf.DUMMYFUNCTION("""COMPUTED_VALUE"""),"Awardextremes, Inc.") -> Awardextremes, Inc. | N20: =IFERROR(__xludf.DUMMYFUNCTION("""COMPUTED_VALUE"""),4.666666666666667) -> 4.6666667 | O20: =IFERROR(__xludf.DUMMYFUNCTION("""COMPUTED_VALUE"""),44778.0) -> 44778 | Q20: =IFERROR(__xludf.DUMMYFUNCTION("""COMPUTED_VALUE"""),"Lordfel Marketing") -> Lordfel Marketing | R20: =IFERROR(__xludf.DUMMYFUNCTION("""COMPUTED_VALUE"""),4.0) -> 4 | S20: =IFERROR(__xludf.DUMMYFUNCTION("""COMPUTED_VALUE"""),45149.0) -> 45149 | U20: =IFERROR(__xludf.DUMMYFUNCTION("""COMPUTED_VALUE"""),"Belview Co., Inc.") -> Belview Co., Inc. | V20: =IFERROR(__xludf.DUMMYFUNCTION("""COMPUTED_VALUE"""),4.833333333333333) -> 4.8333333 | W20: =IFERROR(__xludf.DUMMYFUNCTION("""COMPUTED_VALUE"""),45510.0) -> 45510 | Y20: =IFERROR(__xludf.DUMMYFUNCTION("""COMPUTED_VALUE"""),"DKL Laboratory Supplies") -> DKL Laboratory Supplies | Z20: =IFERROR(__xludf.DUMMYFUNCTION("""COMPUTED_VALUE"""),3.8333333333333335) -> 3.8333333 | AB20: =IFERROR(__xludf.DUMMYFUNCTION("""COMPUTED_VALUE"""),"Chronos Athletics Shop") -> Chronos Athletics Shop | AC20: =IFERROR(__xludf.DUMMYFUNCTION("""COMPUTED_VALUE"""),4.519444444444445) -> 4.5194444 | AE20: =IFERROR(__xludf.DUMMYFUNCTION("""COMPUTED_VALUE"""),"Bobman Trading") -> Bobman Trading | AF20: =IFERROR(__xludf.DUMMYFUNCTION("""COMPUTED_VALUE"""),4.89074074074074) -> 4.8907407
A21: 13 | B21: EA Intertrade General Merchandising, Inc. | E21: 14 | F21: EXPRESS CARDS ENTERPRISES, CO. | I21: 13 | J21: Forefront Book Co., Inc. | M21: =IFERROR(__xludf.DUMMYFUNCTION("""COMPUTED_VALUE"""),"Gift Republic, Inc.") -> Gift Republic, Inc. | N21: =IFERROR(__xludf.DUMMYFUNCTION("""COMPUTED_VALUE"""),4.713333333333334) -> 4.7133333 | O21: =IFERROR(__xludf.DUMMYFUNCTION("""COMPUTED_VALUE"""),44778.0) -> 44778 | Q21: =IFERROR(__xludf.DUMMYFUNCTION("""COMPUTED_VALUE"""),"Lordfel Marketing") -> Lordfel Marketing | R21: =IFERROR(__xludf.DUMMYFUNCTION("""COMPUTED_VALUE"""),4.0) -> 4 | S21: =IFERROR(__xludf.DUMMYFUNCTION("""COMPUTED_VALUE"""),45149.0) -> 45149 | U21: =IFERROR(__xludf.DUMMYFUNCTION("""COMPUTED_VALUE"""),"Abacus Book & Card Corp.") -> Abacus Book & Card Corp. | V21: =IFERROR(__xludf.DUMMYFUNCTION("""COMPUTED_VALUE"""),4.75) -> 4.75 | W21: =IFERROR(__xludf.DUMMYFUNCTION("""COMPUTED_VALUE"""),45512.0) -> 45512 | Y21: =IFERROR(__xludf.DUMMYFUNCTION("""COMPUTED_VALUE"""),"Data Computer Forms, Inc.") -> Data Computer Forms, Inc. | Z21: =IFERROR(__xludf.DUMMYFUNCTION("""COMPUTED_VALUE"""),4.966666666666667) -> 4.9666667 | AB21: =IFERROR(__xludf.DUMMYFUNCTION("""COMPUTED_VALUE"""),"Circuitrocks Electronic Store") -> Circuitrocks Electronic Store | AC21: =IFERROR(__xludf.DUMMYFUNCTION("""COMPUTED_VALUE"""),4.908333333333333) -> 4.9083333 | AE21: =IFERROR(__xludf.DUMMYFUNCTION("""COMPUTED_VALUE"""),"CD Books International, Inc.") -> CD Books International, Inc. | AF21: =IFERROR(__xludf.DUMMYFUNCTION("""COMPUTED_VALUE"""),4.866666666666666) -> 4.8666667
A22: 14 | B22: One Supply | E22: Computer/Peripherals/Software | G22: =average(G23:G27) -> 4.6472222 | I22: Computer/Peripherals/Software | K22: =average(K23:K30) -> 4.9320833 | M22: =IFERROR(__xludf.DUMMYFUNCTION("""COMPUTED_VALUE"""),"Leonard Prints Inc.") -> Leonard Prints Inc. | N22: =IFERROR(__xludf.DUMMYFUNCTION("""COMPUTED_VALUE"""),4.8) -> 4.8 | O22: =IFERROR(__xludf.DUMMYFUNCTION("""COMPUTED_VALUE"""),44789.0) -> 44789 | Q22: =IFERROR(__xludf.DUMMYFUNCTION("""COMPUTED_VALUE"""),"Contrade Integrated Depot") -> Contrade Integrated Depot | R22: =IFERROR(__xludf.DUMMYFUNCTION("""COMPUTED_VALUE"""),4.690833333333334) -> 4.6908333 | S22: =IFERROR(__xludf.DUMMYFUNCTION("""COMPUTED_VALUE"""),45152.0) -> 45152 | U22: =IFERROR(__xludf.DUMMYFUNCTION("""COMPUTED_VALUE"""),"Mostaco Printing") -> Mostaco Printing | V22: =IFERROR(__xludf.DUMMYFUNCTION("""COMPUTED_VALUE"""),4.75) -> 4.75 | W22: =IFERROR(__xludf.DUMMYFUNCTION("""COMPUTED_VALUE"""),45513.0) -> 45513 | Y22: =IFERROR(__xludf.DUMMYFUNCTION("""COMPUTED_VALUE"""),"EIG Metal Engravers") -> EIG Metal Engravers | Z22: =IFERROR(__xludf.DUMMYFUNCTION("""COMPUTED_VALUE"""),4.5) -> 4.5 | AB22: =IFERROR(__xludf.DUMMYFUNCTION("""COMPUTED_VALUE"""),"Colent Marketing Philippines, Inc.") -> Colent Marketing Philippines, Inc. | AC22: =IFERROR(__xludf.DUMMYFUNCTION("""COMPUTED_VALUE"""),5.0) -> 5 | AE22: =IFERROR(__xludf.DUMMYFUNCTION("""COMPUTED_VALUE"""),"COMPUTECHNOLOGIES CORP.") -> COMPUTECHNOLOGIES CORP. | AF22: =IFERROR(__xludf.DUMMYFUNCTION("""COMPUTED_VALUE"""),4.858333333333333) -> 4.8583333
A23: 15 | B23: Commerce Asia Inc. | C23: 4.8125 | E23: 15 | F23: NetAd IT Solutions | G23: 4.7472222 | I23: 14 | J23: Commerce Asia Inc | M23: =IFERROR(__xludf.DUMMYFUNCTION("""COMPUTED_VALUE"""),"Contrade Integrated Depot") -> Contrade Integrated Depot | N23: =IFERROR(__xludf.DUMMYFUNCTION("""COMPUTED_VALUE"""),4.0) -> 4 | O23: =IFERROR(__xludf.DUMMYFUNCTION("""COMPUTED_VALUE"""),44791.0) -> 44791 | Q23: =IFERROR(__xludf.DUMMYFUNCTION("""COMPUTED_VALUE"""),"Polaris Prime Air Tech Corporation") -> Polaris Prime Air Tech Corporation | R23: =IFERROR(__xludf.DUMMYFUNCTION("""COMPUTED_VALUE"""),4.0) -> 4 | S23: =IFERROR(__xludf.DUMMYFUNCTION("""COMPUTED_VALUE"""),45152.0) -> 45152 | U23: =IFERROR(__xludf.DUMMYFUNCTION("""COMPUTED_VALUE"""),"Print Depot Inc.") -> Print Depot Inc. | V23: =IFERROR(__xludf.DUMMYFUNCTION("""COMPUTED_VALUE"""),4.833333333333333) -> 4.8333333 | W23: =IFERROR(__xludf.DUMMYFUNCTION("""COMPUTED_VALUE"""),45514.0) -> 45514 | Y23: =IFERROR(__xludf.DUMMYFUNCTION("""COMPUTED_VALUE"""),"Ergo Contracts Phil., Inc.") -> Ergo Contracts Phil., Inc. | Z23: =IFERROR(__xludf.DUMMYFUNCTION("""COMPUTED_VALUE"""),4.766666666666667) -> 4.7666667 | AB23: =IFERROR(__xludf.DUMMYFUNCTION("""COMPUTED_VALUE"""),"Columbia Technologies, Inc.") -> Columbia Technologies, Inc. | AC23: =IFERROR(__xludf.DUMMYFUNCTION("""COMPUTED_VALUE"""),4.0) -> 4 | AE23: =IFERROR(__xludf.DUMMYFUNCTION("""COMPUTED_VALUE"""),"Chemtrust Global Market, Inc.") -> Chemtrust Global Market, Inc. | AF23: =IFERROR(__xludf.DUMMYFUNCTION("""COMPUTED_VALUE"""),4.775277777777777) -> 4.7752778
A24: 16 | B24: EXPRESS CARDS ENTERPRISES, CO. | E24: 16 | F24: Alpha-Cored Technology Systems, Inc. | G24: 5 | I24: 15 | J24: IEquity Technologies Corporation | M24: =IFERROR(__xludf.DUMMYFUNCTION("""COMPUTED_VALUE"""),"Amazon") -> Amazon | N24: =IFERROR(__xludf.DUMMYFUNCTION("""COMPUTED_VALUE"""),4.2283333333333335) -> 4.2283333 | O24: =IFERROR(__xludf.DUMMYFUNCTION("""COMPUTED_VALUE"""),44793.0) -> 44793 | Q24: =IFERROR(__xludf.DUMMYFUNCTION("""COMPUTED_VALUE"""),"Abacus Book & Card Corp.") -> Abacus Book & Card Corp. | R24: =IFERROR(__xludf.DUMMYFUNCTION("""COMPUTED_VALUE"""),4.666666666666667) -> 4.6666667 | S24: =IFERROR(__xludf.DUMMYFUNCTION("""COMPUTED_VALUE"""),45153.0) -> 45153 | U24: =IFERROR(__xludf.DUMMYFUNCTION("""COMPUTED_VALUE"""),"Crosspoint Paper, Inc.") -> Crosspoint Paper, Inc. | V24: =IFERROR(__xludf.DUMMYFUNCTION("""COMPUTED_VALUE"""),4.833333333333333) -> 4.8333333 | W24: =IFERROR(__xludf.DUMMYFUNCTION("""COMPUTED_VALUE"""),45514.0) -> 45514 | Y24: =IFERROR(__xludf.DUMMYFUNCTION("""COMPUTED_VALUE"""),"Falcon Waterfree Philippines, Inc.") -> Falcon Waterfree Philippines, Inc. | Z24: =IFERROR(__xludf.DUMMYFUNCTION("""COMPUTED_VALUE"""),5.0) -> 5 | AB24: =IFERROR(__xludf.DUMMYFUNCTION("""COMPUTED_VALUE"""),"Commerce Asia, Inc.") -> Commerce Asia, Inc. | AC24: =IFERROR(__xludf.DUMMYFUNCTION("""COMPUTED_VALUE"""),4.748333333333333) -> 4.7483333 | AE24: =IFERROR(__xludf.DUMMYFUNCTION("""COMPUTED_VALUE"""),"Colent Marketing Philippines, Inc.") -> Colent Marketing Philippines, Inc. | AF24: =IFERROR(__xludf.DUMMYFUNCTION("""COMPUTED_VALUE"""),4.5) -> 4.5
A25: 17 | B25: Amalgamated Specialties Corp | E25: 8 | F25: Microsmith Technology Systems, Inc. | G25: 4.8416667 | I25: 16 | J25: Columbia Technologies ,Inc | K25: 4.9583333 | M25: =IFERROR(__xludf.DUMMYFUNCTION("""COMPUTED_VALUE"""),"Rivchem Enterprises") -> Rivchem Enterprises | N25: =IFERROR(__xludf.DUMMYFUNCTION("""COMPUTED_VALUE"""),4.766666666666667) -> 4.7666667 | O25: =IFERROR(__xludf.DUMMYFUNCTION("""COMPUTED_VALUE"""),44798.0) -> 44798 | Q25: =IFERROR(__xludf.DUMMYFUNCTION("""COMPUTED_VALUE"""),"Net Ad IT Solutions") -> Net Ad IT Solutions | R25: =IFERROR(__xludf.DUMMYFUNCTION("""COMPUTED_VALUE"""),4.875) -> 4.875 | S25: =IFERROR(__xludf.DUMMYFUNCTION("""COMPUTED_VALUE"""),45157.0) -> 45157 | U25: =IFERROR(__xludf.DUMMYFUNCTION("""COMPUTED_VALUE"""),"Mostaco Printing") -> Mostaco Printing | V25: =IFERROR(__xludf.DUMMYFUNCTION("""COMPUTED_VALUE"""),4.75) -> 4.75 | W25: =IFERROR(__xludf.DUMMYFUNCTION("""COMPUTED_VALUE"""),45516.0) -> 45516 | Y25: =IFERROR(__xludf.DUMMYFUNCTION("""COMPUTED_VALUE"""),"Gift Republic, Inc.") -> Gift Republic, Inc. | Z25: =IFERROR(__xludf.DUMMYFUNCTION("""COMPUTED_VALUE"""),2.926666666666667) -> 2.9266667 | AB25: =IFERROR(__xludf.DUMMYFUNCTION("""COMPUTED_VALUE"""),"Contrade Integrated Depot") -> Contrade Integrated Depot | AC25: =IFERROR(__xludf.DUMMYFUNCTION("""COMPUTED_VALUE"""),4.6089166666666666) -> 4.6089167 | AE25: =IFERROR(__xludf.DUMMYFUNCTION("""COMPUTED_VALUE"""),"Columbia Technologies, Inc.") -> Columbia Technologies, Inc. | AF25: =IFERROR(__xludf.DUMMYFUNCTION("""COMPUTED_VALUE"""),4.941666666666666) -> 4.9416667
A26: 18 | B26: MOSTACO | C26: 4.7037037 | E26: 18 | F26: Columbia Technologies, Inc. | G26: 4 | I26: 17 | J26: Microsmith Technologies | K26: 4.9416667 | M26: =IFERROR(__xludf.DUMMYFUNCTION("""COMPUTED_VALUE"""),"Contrade Integrated Depot") -> Contrade Integrated Depot | N26: =IFERROR(__xludf.DUMMYFUNCTION("""COMPUTED_VALUE"""),3.8166666666666664) -> 3.8166667 | O26: =IFERROR(__xludf.DUMMYFUNCTION("""COMPUTED_VALUE"""),44799.0) -> 44799 | Q26: =IFERROR(__xludf.DUMMYFUNCTION("""COMPUTED_VALUE"""),"Microsmith Technology System,Inc.") -> Microsmith Technology System,Inc. | R26: =IFERROR(__xludf.DUMMYFUNCTION("""COMPUTED_VALUE"""),4.833333333333333) -> 4.8333333 | S26: =IFERROR(__xludf.DUMMYFUNCTION("""COMPUTED_VALUE"""),45163.0) -> 45163 | U26: =IFERROR(__xludf.DUMMYFUNCTION("""COMPUTED_VALUE"""),"Abacus Book & Card Corp.") -> Abacus Book & Card Corp. | V26: =IFERROR(__xludf.DUMMYFUNCTION("""COMPUTED_VALUE"""),4.75) -> 4.75 | W26: =IFERROR(__xludf.DUMMYFUNCTION("""COMPUTED_VALUE"""),45516.0) -> 45516 | Y26: =IFERROR(__xludf.DUMMYFUNCTION("""COMPUTED_VALUE"""),"Hospeco Philippines, Inc.") -> Hospeco Philippines, Inc. | Z26: =IFERROR(__xludf.DUMMYFUNCTION("""COMPUTED_VALUE"""),4.683333333333334) -> 4.6833333 | AB26: =IFERROR(__xludf.DUMMYFUNCTION("""COMPUTED_VALUE"""),"Creative Juice Digital Printing") -> Creative Juice Digital Printing | AC26: =IFERROR(__xludf.DUMMYFUNCTION("""COMPUTED_VALUE"""),4.629938271604938) -> 4.6299383 | AE26: =IFERROR(__xludf.DUMMYFUNCTION("""COMPUTED_VALUE"""),"Commerce Asia, Inc.") -> Commerce Asia, Inc. | AF26: =IFERROR(__xludf.DUMMYFUNCTION("""COMPUTED_VALUE"""),4.8125) -> 4.8125
A27: Computer/Peripherals/Software | C27: =average(C28:C32) -> 4.8585438 | E27: 19 | F27: iEquity Technologies Corporation | I27: 18 | J27: EXPRESS CARDS ENTERPRISES, CO. | M27: =IFERROR(__xludf.DUMMYFUNCTION("""COMPUTED_VALUE"""),"Atlas Superflags") -> Atlas Superflags | N27: =IFERROR(__xludf.DUMMYFUNCTION("""COMPUTED_VALUE"""),5.0) -> 5 | O27: =IFERROR(__xludf.DUMMYFUNCTION("""COMPUTED_VALUE"""),44800.0) -> 44800 | Q27: =IFERROR(__xludf.DUMMYFUNCTION("""COMPUTED_VALUE"""),"Atlas Superflags") -> Atlas Superflags | R27: =IFERROR(__xludf.DUMMYFUNCTION("""COMPUTED_VALUE"""),4.0) -> 4 | S27: =IFERROR(__xludf.DUMMYFUNCTION("""COMPUTED_VALUE"""),45165.0) -> 45165 | U27: =IFERROR(__xludf.DUMMYFUNCTION("""COMPUTED_VALUE"""),"Mostaco Printing") -> Mostaco Printing | V27: =IFERROR(__xludf.DUMMYFUNCTION("""COMPUTED_VALUE"""),4.75) -> 4.75 | W27: =IFERROR(__xludf.DUMMYFUNCTION("""COMPUTED_VALUE"""),45516.0) -> 45516 | Y27: =IFERROR(__xludf.DUMMYFUNCTION("""COMPUTED_VALUE"""),"Hytec Power, Inc.") -> Hytec Power, Inc. | Z27: =IFERROR(__xludf.DUMMYFUNCTION("""COMPUTED_VALUE"""),3.466666666666667) -> 3.4666667 | AB27: =IFERROR(__xludf.DUMMYFUNCTION("""COMPUTED_VALUE"""),"Crosspoint Paper, Inc.") -> Crosspoint Paper, Inc. | AC27: =IFERROR(__xludf.DUMMYFUNCTION("""COMPUTED_VALUE"""),5.0) -> 5 | AE27: =IFERROR(__xludf.DUMMYFUNCTION("""COMPUTED_VALUE"""),"Contrade Integrated Depot") -> Contrade Integrated Depot | AF27: =IFERROR(__xludf.DUMMYFUNCTION("""COMPUTED_VALUE"""),4.743253968253969) -> 4.743254
A28: 19 | B28: NetAd IT Solutions | C28: 4.8263889 | E28: Printing and Publication | G28: =average(G29:G40) -> 4.8047068 | I28: 19 | J28: Sert Technology Inc. | K28: 5 | M28: =IFERROR(__xludf.DUMMYFUNCTION("""COMPUTED_VALUE"""),"Leonard Prints Inc.") -> Leonard Prints Inc. | N28: =IFERROR(__xludf.DUMMYFUNCTION("""COMPUTED_VALUE"""),4.833333333333333) -> 4.8333333 | O28: =IFERROR(__xludf.DUMMYFUNCTION("""COMPUTED_VALUE"""),44803.0) -> 44803 | Q28: =IFERROR(__xludf.DUMMYFUNCTION("""COMPUTED_VALUE"""),"Microsmith Technology System,Inc.") -> Microsmith Technology System,Inc. | R28: =IFERROR(__xludf.DUMMYFUNCTION("""COMPUTED_VALUE"""),5.0) -> 5 | S28: =IFERROR(__xludf.DUMMYFUNCTION("""COMPUTED_VALUE"""),45166.0) -> 45166 | U28: =IFERROR(__xludf.DUMMYFUNCTION("""COMPUTED_VALUE"""),"EIG Metal Engravers") -> EIG Metal Engravers | V28: =IFERROR(__xludf.DUMMYFUNCTION("""COMPUTED_VALUE"""),4.833333333333333) -> 4.8333333 | W28: =IFERROR(__xludf.DUMMYFUNCTION("""COMPUTED_VALUE"""),45517.0) -> 45517 | Y28: =IFERROR(__xludf.DUMMYFUNCTION("""COMPUTED_VALUE"""),"JC Campit And Michael Berza") -> JC Campit And Michael Berza | Z28: =IFERROR(__xludf.DUMMYFUNCTION("""COMPUTED_VALUE"""),5.0) -> 5 | AB28: =IFERROR(__xludf.DUMMYFUNCTION("""COMPUTED_VALUE"""),"DKL Laboratory Supplies") -> DKL Laboratory Supplies | AC28: =IFERROR(__xludf.DUMMYFUNCTION("""COMPUTED_VALUE"""),3.6666666666666665) -> 3.6666667 | AE28: =IFERROR(__xludf.DUMMYFUNCTION("""COMPUTED_VALUE"""),"Creative Juice Digital Printing") -> Creative Juice Digital Printing | AF28: =IFERROR(__xludf.DUMMYFUNCTION("""COMPUTED_VALUE"""),4.831249999999999) -> 4.83125
A29: 20 | B29: Alpha-Cored Technology Systems, Inc. | C29: 4.9166667 | E29: 20 | F29: Creative Juice Digital Printing | G29: 4.6299383 | I29: 20 | J29: NetAd IT Solutions | K29: 4.7604167 | M29: =IFERROR(__xludf.DUMMYFUNCTION("""COMPUTED_VALUE"""),"Microsmith Technology System,Inc.") -> Microsmith Technology System,Inc. | N29: =IFERROR(__xludf.DUMMYFUNCTION("""COMPUTED_VALUE"""),5.0) -> 5 | O29: =IFERROR(__xludf.DUMMYFUNCTION("""COMPUTED_VALUE"""),44805.0) -> 44805 | Q29: =IFERROR(__xludf.DUMMYFUNCTION("""COMPUTED_VALUE"""),"Net Ad IT Solutions") -> Net Ad IT Solutions | R29: =IFERROR(__xludf.DUMMYFUNCTION("""COMPUTED_VALUE"""),5.0) -> 5 | S29: =IFERROR(__xludf.DUMMYFUNCTION("""COMPUTED_VALUE"""),45181.0) -> 45181 | U29: =IFERROR(__xludf.DUMMYFUNCTION("""COMPUTED_VALUE"""),"Commerce Asia, Inc.") -> Commerce Asia, Inc. | V29: =IFERROR(__xludf.DUMMYFUNCTION("""COMPUTED_VALUE"""),4.791666666666667) -> 4.7916667 | W29: =IFERROR(__xludf.DUMMYFUNCTION("""COMPUTED_VALUE"""),45517.0) -> 45517 | Y29: =IFERROR(__xludf.DUMMYFUNCTION("""COMPUTED_VALUE"""),"Jarm Printing Press") -> Jarm Printing Press | Z29: =IFERROR(__xludf.DUMMYFUNCTION("""COMPUTED_VALUE"""),4.75) -> 4.75 | AB29: =IFERROR(__xludf.DUMMYFUNCTION("""COMPUTED_VALUE"""),"DOOPLO ADVERTISING") -> DOOPLO ADVERTISING | AC29: =IFERROR(__xludf.DUMMYFUNCTION("""COMPUTED_VALUE"""),4.375) -> 4.375 | AE29: =IFERROR(__xludf.DUMMYFUNCTION("""COMPUTED_VALUE"""),"Crosspoint Paper, Inc.") -> Crosspoint Paper, Inc. | AF29: =IFERROR(__xludf.DUMMYFUNCTION("""COMPUTED_VALUE"""),4.944444444444444) -> 4.9444444
A30: 21 | B30: Microsmith Technology Systems, Inc. | C30: 4.8325758 | E30: 21 | F30: Velprint Corporation | I30: 21 | J30: Alpha-Cored Technology Systems Inc. | K30: 5 | M30: =IFERROR(__xludf.DUMMYFUNCTION("""COMPUTED_VALUE"""),"Amazon") -> Amazon | N30: =IFERROR(__xludf.DUMMYFUNCTION("""COMPUTED_VALUE"""),5.0) -> 5 | O30: =IFERROR(__xludf.DUMMYFUNCTION("""COMPUTED_VALUE"""),44810.0) -> 44810 | Q30: =IFERROR(__xludf.DUMMYFUNCTION("""COMPUTED_VALUE"""),"Net Ad IT Solutions") -> Net Ad IT Solutions | R30: =IFERROR(__xludf.DUMMYFUNCTION("""COMPUTED_VALUE"""),4.875) -> 4.875 | S30: =IFERROR(__xludf.DUMMYFUNCTION("""COMPUTED_VALUE"""),45181.0) -> 45181 | U30: =IFERROR(__xludf.DUMMYFUNCTION("""COMPUTED_VALUE"""),"Shelves and Cups Book Store") -> Shelves and Cups Book Store | V30: =IFERROR(__xludf.DUMMYFUNCTION("""COMPUTED_VALUE"""),4.833333333333333) -> 4.8333333 | W30: =IFERROR(__xludf.DUMMYFUNCTION("""COMPUTED_VALUE"""),45517.0) -> 45517 | Y30: =IFERROR(__xludf.DUMMYFUNCTION("""COMPUTED_VALUE"""),"Leonard Prints Inc.") -> Leonard Prints Inc. | Z30: =IFERROR(__xludf.DUMMYFUNCTION("""COMPUTED_VALUE"""),4.816666666666666) -> 4.8166667 | AB30: =IFERROR(__xludf.DUMMYFUNCTION("""COMPUTED_VALUE"""),"Data Computer Forms, Inc.") -> Data Computer Forms, Inc. | AC30: =IFERROR(__xludf.DUMMYFUNCTION("""COMPUTED_VALUE"""),4.25) -> 4.25 | AE30: =IFERROR(__xludf.DUMMYFUNCTION("""COMPUTED_VALUE"""),"Data Computer Forms, Inc.") -> Data Computer Forms, Inc. | AF30: =IFERROR(__xludf.DUMMYFUNCTION("""COMPUTED_VALUE"""),4.952777777777778) -> 4.9527778
A31: 22 | B31: Columbia Technologies, Inc. | E31: 22 | F31: Luminaire Printing and Publication Corp. | G31: 4.8666667 | I31: Cleaning Supplies & Equipment | K31: =average(K32:K39) -> 4.616369 | M31: =IFERROR(__xludf.DUMMYFUNCTION("""COMPUTED_VALUE"""),"PNB Credit Card") -> PNB Credit Card | N31: =IFERROR(__xludf.DUMMYFUNCTION("""COMPUTED_VALUE"""),3.9166666666666665) -> 3.9166667 | O31: =IFERROR(__xludf.DUMMYFUNCTION("""COMPUTED_VALUE"""),44810.0) -> 44810 | Q31: =IFERROR(__xludf.DUMMYFUNCTION("""COMPUTED_VALUE"""),"Abacus Book & Card Corp.") -> Abacus Book & Card Corp. | R31: =IFERROR(__xludf.DUMMYFUNCTION("""COMPUTED_VALUE"""),4.833333333333333) -> 4.8333333 | S31: =IFERROR(__xludf.DUMMYFUNCTION("""COMPUTED_VALUE"""),45181.0) -> 45181 | U31: =IFERROR(__xludf.DUMMYFUNCTION("""COMPUTED_VALUE"""),"Contrade Integrated Depot") -> Contrade Integrated Depot | V31: =IFERROR(__xludf.DUMMYFUNCTION("""COMPUTED_VALUE"""),4.666666666666667) -> 4.6666667 | W31: =IFERROR(__xludf.DUMMYFUNCTION("""COMPUTED_VALUE"""),45521.0) -> 45521 | Y31: =IFERROR(__xludf.DUMMYFUNCTION("""COMPUTED_VALUE"""),"Lordfel Marketing") -> Lordfel Marketing | Z31: =IFERROR(__xludf.DUMMYFUNCTION("""COMPUTED_VALUE"""),5.0) -> 5 | AB31: =IFERROR(__xludf.DUMMYFUNCTION("""COMPUTED_VALUE"""),"Dynamics Electrical Supply and Hardware") -> Dynamics Electrical Supply and Hardware | AC31: =IFERROR(__xludf.DUMMYFUNCTION("""COMPUTED_VALUE"""),4.0) -> 4 | AE31: =IFERROR(__xludf.DUMMYFUNCTION("""COMPUTED_VALUE"""),"Dynamics Electrical Supply and Hardware") -> Dynamics Electrical Supply and Hardware | AF31: =IFERROR(__xludf.DUMMYFUNCTION("""COMPUTED_VALUE"""),4.333333333333333) -> 4.3333333
A32: 23 | B32: iEquity Technologies Corporation | E32: 23 | F32: JARM Printing Press | G32: 4.875 | I32: 22 | J32: Belvedere Cleanvironment Phils., Inc. | M32: =IFERROR(__xludf.DUMMYFUNCTION("""COMPUTED_VALUE"""),"Abenson Ventures, Inc.") -> Abenson Ventures, Inc. | N32: =IFERROR(__xludf.DUMMYFUNCTION("""COMPUTED_VALUE"""),4.833333333333333) -> 4.8333333 | O32: =IFERROR(__xludf.DUMMYFUNCTION("""COMPUTED_VALUE"""),44812.0) -> 44812 | Q32: =IFERROR(__xludf.DUMMYFUNCTION("""COMPUTED_VALUE"""),"Chemtrust Global Market, Inc.") -> Chemtrust Global Market, Inc. | R32: =IFERROR(__xludf.DUMMYFUNCTION("""COMPUTED_VALUE"""),5.0) -> 5 | S32: =IFERROR(__xludf.DUMMYFUNCTION("""COMPUTED_VALUE"""),45182.0) -> 45182 | U32: =IFERROR(__xludf.DUMMYFUNCTION("""COMPUTED_VALUE"""),"Printing Shop PrintPilipinas.com") -> Printing Shop PrintPilipinas.com | V32: =IFERROR(__xludf.DUMMYFUNCTION("""COMPUTED_VALUE"""),4.833333333333333) -> 4.8333333 | W32: =IFERROR(__xludf.DUMMYFUNCTION("""COMPUTED_VALUE"""),45523.0) -> 45523 | Y32: =IFERROR(__xludf.DUMMYFUNCTION("""COMPUTED_VALUE"""),"Luminaire Printing And Publishing Corp.") -> Luminaire Printing And Publishing Corp. | Z32: =IFERROR(__xludf.DUMMYFUNCTION("""COMPUTED_VALUE"""),4.785714285714286) -> 4.7857143 | AB32: =IFERROR(__xludf.DUMMYFUNCTION("""COMPUTED_VALUE"""),"EA Intertrade General Merchandising, Inc.") -> EA Intertrade General Merchandising, Inc. | AC32: =IFERROR(__xludf.DUMMYFUNCTION("""COMPUTED_VALUE"""),5.0) -> 5 | AE32: =IFERROR(__xludf.DUMMYFUNCTION("""COMPUTED_VALUE"""),"ECOSHIFT CORPORATION") -> ECOSHIFT CORPORATION | AF32: =IFERROR(__xludf.DUMMYFUNCTION("""COMPUTED_VALUE"""),4.966666666666667) -> 4.9666667
